Workbook

Sheet Instruções
A1: Saúde Pet | Levantamento de produtos do fornecedor
A2: Fornecedor 01: Casa de Rações Filhos de 4 Patas (Ribeirão Preto/SP) | Contato: (16) 99428-8613
A4: Margem padrão aplicada | B4: 0.4 | C4: Altere aqui para mudar a margem de toda a aba Catálogo de uma vez.
A6: Como usar esta planilha
A7: Células em AZUL | C7: são as que você preenche (custo, código de barras, estoque).
A8: Célula AMARELA (B4) | C8: é a margem padrão. Hoje está em 40%.
A9: Coluna J (Preço de venda) | C9: é calculada sozinha: custo x (1 + margem). Não digite nada nela.
A10: Coluna I (Margem) | C10: vem da margem padrão. Só edite se um item específico precisar de margem diferente.
A11: Coluna K (Preço na loja) | C11: é o preço de etiqueta que apareceu nas fotos. Serve de referência, não é o seu custo.
A12: Linha 3 do Catálogo | C12: é um EXEMPLO preenchido. Apague antes de subir para a plataforma.
A14: Roteiro do levantamento na loja
A15: 1. Peça a tabela de preços em arquivo (planilha, PDF ou foto legível). Confirme se o preço é de custo/atacado para você ou preço de balcão.
A16: 2. Confirme a condição comercial: prazo de pagamento, pedido mínimo, se o preço muda por volume e com que frequência a tabela é reajustada.
A17: 3. Passe corredor por corredor e fotografe: frente da embalagem, tabela nutricional e o código de barras. O EAN é o que evita cadastro duplicado depois.
A18: 4. Para cada item registre: marca, linha, sabor, público (cão/gato/filhote/adulto/castrado), peso e a unidade de venda (saco, pacote, unidade, fardo com X).
A19: 5. Anote a disponibilidade real. Produto que ele só traz sob encomenda precisa de aviso de prazo na plataforma.
A20: 6. Comece com os campeões de giro (rações 15 kg, tapete higiênico, areia, petiscos) e deixe acessórios e roupas para uma segunda leva.
A21: 7. Marque quem é frágil ou pesado. Saco de 15 kg muda a conta do frete e da sua logística de retirada.
A22: 8. Ao fechar, valide 5 itens do seu preço final contra o preço do mercado local. Margem de 40% em ração de marca costuma ficar acima do praticado.
A24: Origem dos dados
A25: Os produtos da aba Catálogo foram identificados a partir de 50 fotos tiradas na loja em 26/08/2026 (lote 1: Fotos 1 a 9; lote 2: IMG_4289 a IMG_4298; lote 3: IMG_4279 a IMG_4288; lote 4: IMG_4259 a IMG_4278; lote 5: 1 foto avulsa). Onde a embalagem apareceu parcialmente, o item está marcado como CONFIRMAR na coluna Observações.
A26: Os valores da coluna K são etiquetas visíveis nas fotos. Nenhum custo de fornecedor foi informado até aqui, por isso a coluna H está vazia.
A27: Pesos, sabores e códigos de barras precisam ser conferidos na embalagem física antes do cadastro definitivo.

Sheet Catálogo
A1: ID | B1: Categoria | C1: Marca | D1: Produto | E1: Variação / Sabor | F1: Peso / Tamanho | G1: Unidade de venda | H1: Custo fornecedor (R$) | I1: Margem | J1: Preço de venda (R$) | K1: Preço na loja (R$) | L1: Código de barras (EAN) | M1: Estoque | N1: Foto | O1: Observações
A2: EX | B2: Ração cão | C2: Golden (PremieRpet) | D2: Golden Formula Cães Adultos | E2: Frango e arroz - porte pequeno | F2: 15 kg | G2: Saco | H2: 150 | I2: =Instruções!$B$4 -> 0.4 | J2: =IF(H2="","",H2*(1+I2)) -> 210 | K2: 196.5 | L2: 7896588300000 | M2: 8 | N2: Foto 9 | O2: LINHA DE EXEMPLO - apague antes do cadastro
A3: 1 | B3: Ração cão | C3: Golden (PremieRpet) | D3: Golden Formula Cães Adultos | E3: Frango e arroz - porte pequeno | F3: 15 kg | G3: Saco | I3: =Instruções!$B$4 -> 0.4 | J3: =IF(H3="","",H3*(1+I3)) | K3: 196.5 | N3: Foto 9
A4: 2 | B4: Ração cão | C4: Golden (PremieRpet) | D4: Golden Formula Cães Adultos | E4: Frango e arroz | F4: 10,1 kg | G4: Saco | I4: =Instruções!$B$4 -> 0.4 | J4: =IF(H4="","",H4*(1+I4)) | N4: Foto 9 | O4: CONFIRMAR linha e público na embalagem
A5: 3 | B5: Ração cão | C5: Purina | D5: Dog Chow Adultos Minis e Pequenos | E5: Carne e frango | F5: 15 kg | G5: Saco | I5: =Instruções!$B$4 -> 0.4 | J5: =IF(H5="","",H5*(1+I5)) | K5: 175.9 | N5: Foto 9
A6: 4 | B6: Ração cão | C6: Vitta | D6: Vitta Natural Cães Adultos | E6: Frango e arroz - porte pequeno | F6: 15 kg | G6: Saco | I6: =Instruções!$B$4 -> 0.4 | J6: =IF(H6="","",H6*(1+I6)) | K6: 140 | N6: Foto 9
A7: 5 | B7: Ração cão | C7: Vitta | D7: Vitta Natural Cães Filhotes | E7: Frango e arroz - porte pequeno | F7: CONFIRMAR | G7: Saco | I7: =Instruções!$B$4 -> 0.4 | J7: =IF(H7="","",H7*(1+I7)) | N7: Foto 5 | O7: CONFIRMAR peso
A8: 6 | B8: Ração cão | C8: Flock | D8: Flock Adultos | E8: Carne | F8: 15 kg | G8: Saco | I8: =Instruções!$B$4 -> 0.4 | J8: =IF(H8="","",H8*(1+I8)) | K8: 77 | N8: Foto 9 | O8: Item de entrada, bom para atrair preço
A9: 7 | B9: Ração cão | C9: Nutriva | D9: Nutriva Select Adultos Pequeno Porte | E9: Frango e arroz | F9: 15 kg | G9: Saco | I9: =Instruções!$B$4 -> 0.4 | J9: =IF(H9="","",H9*(1+I9)) | N9: Foto 8 | O9: Premium especial, 24% proteína
A10: 8 | B10: Ração cão | C10: Spert | D10: Spert Cães Adultos | E10: Todos os portes | F10: 15 kg | G10: Saco | I10: =Instruções!$B$4 -> 0.4 | J10: =IF(H10="","",H10*(1+I10)) | N10: Foto 9 | O10: CONFIRMAR sabor
A11: 9 | B11: Ração cão | C11: Special Dog | D11: Special Dog Gold Adultos | E11: CONFIRMAR | F11: 15 kg | G11: Saco | I11: =Instruções!$B$4 -> 0.4 | J11: =IF(H11="","",H11*(1+I11)) | N11: Foto 9 | O11: CONFIRMAR sabor e linha
A12: 10 | B12: Ração cão | C12: Special Dog | D12: Special Dog Ultralife Premium Especial | E12: Frango - adultos raças pequenas | F12: 3 kg | G12: Saco | I12: =Instruções!$B$4 -> 0.4 | J12: =IF(H12="","",H12*(1+I12)) | N12: Foto 5 | O12: Zero corantes e aromatizantes
A13: 11 | B13: Ração cão | C13: Finotrato | D13: Finotrato Life Cães Adultos | E13: Cordeiro e arroz - raças pequenas e médias | F13: CONFIRMAR | G13: Saco | I13: =Instruções!$B$4 -> 0.4 | J13: =IF(H13="","",H13*(1+I13)) | N13: Foto 5 | O13: CONFIRMAR peso
A14: 12 | B14: Ração cão | C14: Finotrato | D14: Finotrato Life Cães Adultos | E14: Frango e arroz | F14: 15 kg | G14: Saco | I14: =Instruções!$B$4 -> 0.4 | J14: =IF(H14="","",H14*(1+I14)) | N14: Foto 9
A15: 13 | B15: Ração cão | C15: Begacão | D15: Begacão Premium Natural Adultos | E15: Todos os portes | F15: 7 kg | G15: Saco | I15: =Instruções!$B$4 -> 0.4 | J15: =IF(H15="","",H15*(1+I15)) | N15: Foto 5
A16: 14 | B16: Ração cão | C16: Dog Choni | D16: Dog Choni Cães Adultos | E16: Carne e arroz | F16: CONFIRMAR | G16: Saco | I16: =Instruções!$B$4 -> 0.4 | J16: =IF(H16="","",H16*(1+I16)) | N16: Fotos 5 e 9 | O16: CONFIRMAR grafia da marca e peso
A17: 15 | B17: Ração cão | C17: Grupo Tosi | D17: Naturale / Agromix Filhotes | E17: Todas as raças | F17: 10,1 kg | G17: Saco | I17: =Instruções!$B$4 -> 0.4 | J17: =IF(H17="","",H17*(1+I17)) | N17: Foto 5 | O17: CONFIRMAR nome exato da linha
A18: 16 | B18: Ração cão | C18: Grupo Tosi | D18: Linha com sulfato de condroitina | E18: Suporte articular | F18: 10,1 kg | G18: Saco | I18: =Instruções!$B$4 -> 0.4 | J18: =IF(H18="","",H18*(1+I18)) | N18: Foto 9 | O18: CONFIRMAR marca e nome completo
A19: 17 | B19: Ração gato | C19: Special Cat | D19: Special Cat Premium Gatos Filhotes | E19: Mix de carnes | F19: 10,1 kg | G19: Saco | I19: =Instruções!$B$4 -> 0.4 | J19: =IF(H19="","",H19*(1+I19)) | N19: Foto 5
A20: 18 | B20: Ração gato | C20: Special Cat | D20: Special Cat Premium Gatos Adultos | E20: Peixe | F20: 10,1 kg | G20: Saco | I20: =Instruções!$B$4 -> 0.4 | J20: =IF(H20="","",H20*(1+I20)) | N20: Foto 5 | O20: Aparece em duas variações de peixe, conferir
A21: 19 | B21: Ração gato | C21: Gran Plus | D21: Gran Plus Gourmet Gatos Adultos Castrados | E21: Salmão e frango | F21: CONFIRMAR | G21: Saco | I21: =Instruções!$B$4 -> 0.4 | J21: =IF(H21="","",H21*(1+I21)) | N21: Foto 5 | O21: CONFIRMAR peso
A22: 20 | B22: Ração gato | C22: Gran Plus | D22: Gran Plus Menu Gatos | E22: CONFIRMAR | F22: 10,1 kg | G22: Saco | I22: =Instruções!$B$4 -> 0.4 | J22: =IF(H22="","",H22*(1+I22)) | N22: Foto 9 | O22: CONFIRMAR sabor
A23: 21 | B23: Petisco cão | C23: Golden (PremieRpet) | D23: Golden Cookie | E23: Original - adultos porte pequeno | F23: CONFIRMAR | G23: Pacote | I23: =Instruções!$B$4 -> 0.4 | J23: =IF(H23="","",H23*(1+I23)) | K23: 19.5 | N23: Foto 6 | O23: CONFIRMAR gramatura
A24: 22 | B24: Petisco cão | C24: Special Dog | D24: Special Dog Ultralife Biscoitos Assados | E24: Frutas vermelhas | F24: CONFIRMAR | G24: Pacote | I24: =Instruções!$B$4 -> 0.4 | J24: =IF(H24="","",H24*(1+I24)) | K24: 16.3 | N24: Foto 6 | O24: Lançamento, CONFIRMAR gramatura
A25: 23 | B25: Petisco cão | C25: Doogs | D25: Doogs Biscoito | E25: Frango | F25: CONFIRMAR | G25: Pacote | I25: =Instruções!$B$4 -> 0.4 | J25: =IF(H25="","",H25*(1+I25)) | N25: Foto 5 | O25: CONFIRMAR gramatura
A26: 24 | B26: Petisco cão | C26: Doogs | D26: Doogs Original | E26: Alimento específico para cães | F26: CONFIRMAR | G26: Pacote | I26: =Instruções!$B$4 -> 0.4 | J26: =IF(H26="","",H26*(1+I26)) | N26: Foto 6 | O26: CONFIRMAR variação e preço
A27: 25 | B27: Higiene | C27: Brincalhão | D27: Tapete Higiênico Premium | E27: Cães | F27: Pacote com 6 un. | G27: Pacote | I27: =Instruções!$B$4 -> 0.4 | J27: =IF(H27="","",H27*(1+I27)) | K27: 19.8 | N27: Fotos 6 e 7 | O27: Alto giro, priorizar no cadastro
A28: 26 | B28: Higiene | C28: Brincat | D28: Areia Sanitária Biodegradável | E28: Capim-limão - grãos finos | F28: 2 kg | G28: Pacote | I28: =Instruções!$B$4 -> 0.4 | J28: =IF(H28="","",H28*(1+I28)) | N28: Foto 5
A29: 27 | B29: Higiene | C29: Brincat | D29: Areia Sanitária Biodegradável | E29: Natural - grãos finos | F29: 2 kg | G29: Pacote | I29: =Instruções!$B$4 -> 0.4 | J29: =IF(H29="","",H29*(1+I29)) | N29: Foto 5
A30: 28 | B30: Higiene | C30: Pipicat (Kelco) | D30: Aditivo Antiodor para Areia | E30: Campestre | F30: 500 g | G30: Pacote | I30: =Instruções!$B$4 -> 0.4 | J30: =IF(H30="","",H30*(1+I30)) | K30: 18 | N30: Foto 7
A31: 29 | B31: Higiene | C31: Pipicat (Kelco) | D31: Aditivo Antiodor para Areia | E31: Floral | F31: 500 g | G31: Pacote | I31: =Instruções!$B$4 -> 0.4 | J31: =IF(H31="","",H31*(1+I31)) | K31: 18 | N31: Foto 7
A32: 30 | B32: Outros animais | C32: CC-Albium | D32: Alimento Completo para Pássaros | E32: Papinha para filhotes | F32: 250 g | G32: Pote | I32: =Instruções!$B$4 -> 0.4 | J32: =IF(H32="","",H32*(1+I32)) | K32: 28.5 | N32: Fotos 6 e 7
A33: 31 | B33: Outros animais | C33: Indubras | D33: Suplemento vitamínico e mineral | E33: Animais de pequeno a grande porte | F33: CONFIRMAR | G33: Caixa | I33: =Instruções!$B$4 -> 0.4 | J33: =IF(H33="","",H33*(1+I33)) | N33: Foto 7 | O33: CONFIRMAR nome do produto (Ceva...)
A34: 32 | B34: Acessório | C34: Diversos | D34: Coleira de nylon estampada | E34: Diversas estampas e cores | F34: P / M / G | G34: Unidade | I34: =Instruções!$B$4 -> 0.4 | J34: =IF(H34="","",H34*(1+I34)) | N34: Fotos 1 e 2 | O34: Cadastrar por tamanho, foto por estampa
A35: 33 | B35: Acessório | C35: Diversos | D35: Guia de nylon estampada | E35: Diversas estampas e cores | F35: Único | G35: Unidade | I35: =Instruções!$B$4 -> 0.4 | J35: =IF(H35="","",H35*(1+I35)) | N35: Fotos 1 e 2
A36: 34 | B36: Acessório | C36: Diversos | D36: Peitoral com guia (conjunto) | E36: Nylon estampado | F36: P / M / G | G36: Conjunto | I36: =Instruções!$B$4 -> 0.4 | J36: =IF(H36="","",H36*(1+I36)) | N36: Fotos 1 e 2 | O36: Melhor vendido como kit na plataforma
A37: 35 | B37: Acessório | C37: Diversos | D37: Guia de corda com mosquetão | E37: Vermelha, azul, preta, rosa | F37: Único | G37: Unidade | I37: =Instruções!$B$4 -> 0.4 | J37: =IF(H37="","",H37*(1+I37)) | K37: 35 | N37: Foto 1 | O37: Etiqueta de 35,00 visível, CONFIRMAR a qual modelo pertence
A38: 36 | B38: Acessório | C38: Diversos | D38: Guia de corda com amortecedor (mola) | E38: Rosa e vermelha | F38: Único | G38: Unidade | I38: =Instruções!$B$4 -> 0.4 | J38: =IF(H38="","",H38*(1+I38)) | N38: Foto 1
A39: 37 | B39: Acessório | C39: Diversos | D39: Coleira de couro | E39: Vermelha | F39: M / G | G39: Unidade | I39: =Instruções!$B$4 -> 0.4 | J39: =IF(H39="","",H39*(1+I39)) | N39: Foto 1
A40: 38 | B40: Acessório | C40: Diversos | D40: Coleira/enforcador de corrente | E40: Metal | F40: M / G | G40: Unidade | I40: =Instruções!$B$4 -> 0.4 | J40: =IF(H40="","",H40*(1+I40)) | N40: Fotos 1 e 2
...

Sheet Campos da plataforma
A1: Campos mínimos para cadastrar um produto no marketplace Saúde Pet
A3: Campo | B3: Obrigatório | C3: Observação
A4: SKU interno | B4: Sim | C4: Padrão sugerido: FOR01-CATEGORIA-0001 (FOR01 = Filhos de 4 Patas)
A5: Nome do produto | B5: Sim | C5: Marca + linha + sabor + peso. Ex: Golden Formula Adultos Frango e Arroz 15 kg
A6: Código de barras (EAN) | B6: Sim | C6: Evita duplicidade quando entrarem novos fornecedores
A7: Categoria e subcategoria | B7: Sim | C7: Cão / Gato / Pássaro > Ração, Petisco, Higiene, Acessório
A8: Marca | B8: Sim | C8: Vira filtro na busca
A9: Peso ou tamanho | B9: Sim | C9: Também usado no cálculo de frete
A10: Peso bruto para frete | B10: Sim | C10: Saco de 15 kg muda a logística de retirada e entrega
A11: Custo do fornecedor | B11: Sim | C11: Não aparece para o cliente
A12: Margem aplicada | B12: Sim | C12: Padrão 40%, ajustável por item
A13: Preço de venda | B13: Sim | C13: Gerado pelo custo x margem
A14: Estoque ou disponibilidade | B14: Sim | C14: Se for sob encomenda, informar prazo na descrição
... A18: Prazo de reposição | B18: Não | C18: Útil quando o item estiver zerado
